Workbook
Name ManufacturerList: 'Списки'!$A$2:$A$7
Name Алттранс: 'Списки'!$B$2:$B$13
Name СВЭЛ: 'Списки'!$C$2:$C$13
Name МЭТЗ: 'Списки'!$D$2:$D$13
Name Электрощит: 'Списки'!$E$2:$E$12
Name Трансформер: 'Списки'!$F$2:$F$7
Name Алагеум: 'Списки'!$G$2:$G$21
Name empty_list: 'Списки'!$H$2:$H$2
Name steel_type: 'Списки'!$I$2:$I$3
Name steel_thickness: 'Списки'!$J$2:$J$5
Name channel_size: 'Списки'!$K$2:$K$13
Name ral_colors: 'Списки'!$L$2:$L$10
Name grid_company: 'Списки'!$M$2:$M$6
Name manuf_pvr: 'Списки'!$N$2:$N$6
Name manuf_re: 'Списки'!$O$2:$O$5
Name manuf_rps: 'Списки'!$P$2:$P$4
Name manuf_av: 'Списки'!$Q$2:$Q$7
Name yn: 'Списки'!$R$2:$R$3
Name ruvn_type: 'Списки'!$S$2:$S$4
Name ruvn_switch: 'Списки'!$T$2:$T$4
Name ruvn_nom: 'Списки'!$U$2:$U$4
Name volt: 'Списки'!$V$2:$V$3
Name fuse: 'Списки'!$W$2:$W$5
Name fuse_nom: 'Списки'!$X$2:$X$16
Name cable: 'Списки'!$Y$2:$Y$3
Name pvr: 'Списки'!$Z$2:$Z$8
Name tt: 'Списки'!$AA$2:$AA$13
Name av_nom: 'Списки'!$AB$2:$AB$21

Sheet Навигация
B2: ⚡ ГЛАВНОЕ МЕНЮ: КТПН КОНФИГУРАТОР
B4: 📊 ИНТЕРАКТИВНЫЙ РАСЧЕТ И ПРОВЕРКА
B5: 📐 ГАБАРИТЫ И МЕТАЛЛОКОНСТРУКЦИЯ
B6: 🏭 ПРИКАЗ НА ПРОИЗВОДСТВО
B7: 📋 ЧЕК-ЛИСТ ОТК
B8: ⚙️ БД Аппаратов РУНН (АВ, РЕ, ПВР)
B9: 📖 Справочник Трансформаторов (Сводный)
B10: 📖 Справочник (Алттранс)
B11: 📖 Справочник (СВЭЛ)
B12: 📖 Справочник (МЭТЗ)
B13: 📖 Справочник (Электрощит)
B14: 📖 Справочник (Трансформер)
B15: 📖 Справочник (Алагеум / КТЗ)

Sheet Расчет КТПН
A1: ИНТЕРАКТИВНЫЙ РАСЧЕТ ГАБАРИТОВ И КОМПОНОВКА КТПН
A3: Сетевая компания: | B3: Россети
A4: Производитель: | B4: Алагеум
A5: Марка трансформатора: | B5: ТМГ-400 (Алагеум)
A7: Производитель | B7: Длина TMG | C7: Ширина TMG | D7: Высота TMG | E7: Масса TMG | F7: Ток НН (А)
A8: =IFERROR(VLOOKUP(B5, БД_Трансформаторы!$A$2:$K$200, 2, FALSE), 0) | B8: =IFERROR(VLOOKUP(B5, БД_Трансформаторы!$A$2:$K$200, 4, FALSE), 0) | C8: =IFERROR(VLOOKUP(B5, БД_Трансформаторы!$A$2:$K$200, 5, FALSE), 0) | D8: =IFERROR(VLOOKUP(B5, БД_Трансформаторы!$A$2:$K$200, 6, FALSE), 0) | E8: =IFERROR(VLOOKUP(B5, БД_Трансформаторы!$A$2:$K$200, 7, FALSE), 0) | F8: =IFERROR(VLOOKUP(B5, БД_Трансформаторы!$A$2:$K$200, 8, FALSE), 0)
A10: --- Конструктив корпуса ---
A11: Тип стали корпуса: | B11: Холоднокатаная (х.к.) | C11: Толщина корпуса (мм): | D11: 2.0
A12: Основание (Швеллер №): | B12: 10П
A13: Цвет корпуса (RAL): | B13: RAL 7035 (Светло-серый) | C13: Цвет дверей (RAL): | D13: RAL 7040 (Серый окованный)
A15: --- Габаритные настройки отсеков ---
A16: Длина РУВН (мм): | B16: 1300
A17: Длина РУНН (мм): | B17: 600
A18: Допуск на отсек ТР (мм): | B18: 300
A19: Буфер по длине КТПН (мм): | B19: 10
A21: --- Ввод РУВН ---
A22: Напряжение РУВН: | B22: 10 кВ
A23: Отсек РУВН: | B23: Тупиковая
A24: Разъединитель РУВН: | B24: ВНА | C24: Ном-л РУВН (А): | D24: 630
A25: Предохранитель ПКТ: | B25: ПКТ-101 | C25: Ном-л ПКТ: | D25: 31.5А
A26: Исполнение ввода: | B26: Кабельный
A27: Установка ОПН (РУВН): | B27: Да
A28: --- Ввод РУНН ---
A29: Вводной ПВР (NH): | B29: Да | C29: Номинал ПВР (А): | D29: 630
A30: Производитель ПВР: | B30: CHINT
A31: Вводной рубильник (РЕ): | B31: Нет | C31: Номинал РЕ (А): | D31: 630
A32: Производитель РЕ: | B32: КЭАЗ
A33: Вводной АВ: | B33: Нет | C33: Номинал АВ (А): | D33: 630
A34: Производитель АВ: | B34: Контактор
A35: Установка ОПН (РУНН): | B35: Да
A36: Наличие ТТ на вводе: | B36: Да | C36: Номинал ТТ: | D36: 600/5
A37: Доп. комплект ТТ (КИП): | B37: Нет | C37: Номинал ТТ КИП: | D37: 600/5
A38: Наличие счетчика на вводе: | B38: Да
A39: --- Отходящие линии РУНН ---
A40: Установка Автоматов (АВ): | B40: Да | C40: Кол-во АВ (шт): | D40: 2
A41: Бренд отходящих АВ: | B41: IEK
A42: Установка РПС: | B42: Нет | C42: Кол-во РПС (шт): | D42: 0
A43: Бренд отходящих РПС: | B43: CHINT
A44: Исполнение вывода: | B44: Кабельный
A46: =IF(IF(B29="Да",VALUE(D29),0)>=F8,"✅ ПРОВЕРКА ПРОЙДЕНА: Номинал вводного устройства достаточен для мощности ТМГ",IF(IF(B31="Да",VALUE(D31),0)>=F8,"✅ ПРОВЕРКА ПРОЙДЕНА: Номинал вводного устройства достаточен для мощности ТМГ",IF(IF(B33="Да",VALUE(D33),0)>=F8,"✅ ПРОВЕРКА ПРОЙДЕНА: Номинал вводного устройства достаточен для мощности ТМГ","🛑 ОШИБКА ПРОЕКТИРОВАНИЯ: Номинал ввода меньше номинального тока трансформатора!")))
...

Sheet БД_Трансформаторы
A1: Марка | B1: Производитель | C1: Мощность (кВА) | D1: Длина (мм) | E1: Ширина (мм) | F1: Высота (мм) | G1: Масса (кг) | H1: Ном. Ток НН (А) | I1: Шины РУВН | J1: Шины РУНН (ввод) | K1: Шина PE/PEN
A2: ТМГ-25 | B2: Алттранс | C2: 25 | D2: 780 | E2: 440 | F2: 905 | G2: 260 | H2: 36 | I2: 50х5 | J2: 40х4 | K2: 40х4
A3: ТМГ-40 | B3: Алттранс | C3: 40 | D3: 830 | E3: 440 | F3: 960 | G3: 310 | H3: 57 | I3: 50х5 | J3: 40х4 | K3: 40х4
A4: ТМГ-63 | B4: Алттранс | C4: 63 | D4: 810 | E4: 575 | F4: 925 | G4: 380 | H4: 90 | I4: 50х5 | J4: 40х4 | K4: 40х4
A5: ТМГ-100 | B5: Алттранс | C5: 100 | D5: 830 | E5: 645 | F5: 1045 | G5: 490 | H5: 144 | I5: 50х5 | J5: 40х4 | K5: 40х4
A6: ТМГ-160 | B6: Алттранс | C6: 160 | D6: 925 | E6: 775 | F6: 1045 | G6: 680 | H6: 230 | I6: 50х5 | J6: 40х4 | K6: 40х4
A7: ТМГ-250 | B7: Алттранс | C7: 250 | D7: 1110 | E7: 835 | F7: 1130 | G7: 895 | H7: 360 | I7: 50х5 | J7: 40х5 | K7: 40х4
A8: ТМГ-400 | B8: Алттранс | C8: 400 | D8: 1255 | E8: 960 | F8: 1235 | G8: 1200 | H8: 577 | I8: 50х5 | J8: 50х5 | K8: 40х5
A9: ТМГ-630 | B9: Алттранс | C9: 630 | D9: 1450 | E9: 1000 | F9: 1430 | G9: 1720 | H9: 909 | I9: 50х5 | J9: 80х6 | K9: 50х5
A10: ТМГ-1000 | B10: Алттранс | C10: 1000 | D10: 1735 | E10: 1130 | F10: 1450 | G10: 2400 | H10: 1443 | I10: 50х5 | J10: 100х8 | K10: 80х6
A11: ТМГ-1250 | B11: Алттранс | C11: 1250 | D11: 1791 | E11: 1070 | F11: 1856 | G11: 3135 | H11: 1803 | I11: 50х5 | J11: 2х(80х8) | K11: 80х8
A12: ТМГ-1600 | B12: Алттранс | C12: 1600 | D12: 1955 | E12: 1145 | F12: 1840 | G12: 3500 | H12: 2308 | I12: 50х5 | J12: 2х(100х10) | K12: 100х8
A13: ТМГ-2500 | B13: Алттранс | C13: 2500 | D13: 2300 | E13: 1350 | F13: 2100 | G13: 5500 | H13: 3607 | I13: 50х5 | J13: 3х(100х10) | K13: 100х10
... A74: ТСЛ-2500 (Алагеум) | B74: Алагеум | C74: 2500 | D74: 2000 | E74: 1200 | F74: 2350 | G74: 6700 | H74: 3607 | I74: 50х5 | J74: 3х(100х10) | K74: 100х10

Sheet БД_Аппараты_РУНН
A1: Тип аппарата | B1: Производитель | C1: Страна / Статус | D1: Серия / Модель | E1: Диапазон номинальных токов (А)
A2: Автоматический выключатель (АВ) | B2: КЭАЗ | C2: Россия | D2: OptiMat D, OptiMat A, ВА57 | E2: 16 - 4000 А
A3: Автоматический выключатель (АВ) | B3: Контактор | C3: Россия | D3: ПРОТОН, ЭЛЕКТРОН, ВА | E3: 16 - 6300 А
A4: Автоматический выключатель (АВ) | B4: IEK | C4: Россия / Китай | D4: ВА88, ВА07 | E4: 16 - 2000 А
A5: Автоматический выключатель (АВ) | B5: EKF | C5: Россия / Китай | D5: AVERES, PROxima | E5: 16 - 4000 А
A6: Автоматический выключатель (АВ) | B6: ДКС (DKC) | C6: Россия | D6: YON MAX | E6: 16 - 1600 А
A7: Автоматический выключатель (АВ) | B7: CHINT | C7: Китай | D7: NM8N, NXm, NA8G | E7: 16 - 6300 А
A8: Рубильник открытый (РЕ) | B8: КЭАЗ | C8: Россия | D8: РЕ19, ВР32 | E8: 100 - 4000 А
A9: Рубильник открытый (РЕ) | B9: Кореневский завод НВА | C9: Россия | D9: ВР32, РЕ19 | E9: 100 - 1000 А
A10: Рубильник открытый (РЕ) | B10: IEK | C10: Россия / Китай | D10: ВР32 | E10: 100 - 630 А
A11: Рубильник открытый (РЕ) | B11: CHINT | C11: Китай | D11: NH40 | E11: 160 - 3150 А
A12: Рубильник с предохранителями (РПС) | B12: Кореневский завод НВА | C12: Россия | D12: РПС, РПБ | E12: 100 - 630 А
... A19: Предохранитель-разъединитель (ПВР / NH) | B19: Апатор-Электро | C19: Россия | D19: ARS | E19: 160 - 1250 А

Sheet Алттранс
A1: Марка | B1: Производитель | C1: Мощность (кВА) | D1: Длина (мм) | E1: Ширина (мм) | F1: Высота (мм) | G1: Масса (кг) | H1: Ном. Ток НН (А) | I1: Шины РУВН | J1: Шины РУНН (ввод) | K1: Шина PE/PEN
A2: ТМГ-25 | B2: Алттранс | C2: 25 | D2: 780 | E2: 440 | F2: 905 | G2: 260 | H2: 36 | I2: 50х5 | J2: 40х4 | K2: 40х4
A3: ТМГ-40 | B3: Алттранс | C3: 40 | D3: 830 | E3: 440 | F3: 960 | G3: 310 | H3: 57 | I3: 50х5 | J3: 40х4 | K3: 40х4
A4: ТМГ-63 | B4: Алттранс | C4: 63 | D4: 810 | E4: 575 | F4: 925 | G4: 380 | H4: 90 | I4: 50х5 | J4: 40х4 | K4: 40х4
A5: ТМГ-100 | B5: Алттранс | C5: 100 | D5: 830 | E5: 645 | F5: 1045 | G5: 490 | H5: 144 | I5: 50х5 | J5: 40х4 | K5: 40х4
A6: ТМГ-160 | B6: Алттранс | C6: 160 | D6: 925 | E6: 775 | F6: 1045 | G6: 680 | H6: 230 | I6: 50х5 | J6: 40х4 | K6: 40х4
A7: ТМГ-250 | B7: Алттранс | C7: 250 | D7: 1110 | E7: 835 | F7: 1130 | G7: 895 | H7: 360 | I7: 50х5 | J7: 40х5 | K7: 40х4
A8: ТМГ-400 | B8: Алттранс | C8: 400 | D8: 1255 | E8: 960 | F8: 1235 | G8: 1200 | H8: 577 | I8: 50х5 | J8: 50х5 | K8: 40х5
A9: ТМГ-630 | B9: Алттранс | C9: 630 | D9: 1450 | E9: 1000 | F9: 1430 | G9: 1720 | H9: 909 | I9: 50х5 | J9: 80х6 | K9: 50х5
A10: ТМГ-1000 | B10: Алттранс | C10: 1000 | D10: 1735 | E10: 1130 | F10: 1450 | G10: 2400 | H10: 1443 | I10: 50х5 | J10: 100х8 | K10: 80х6
A11: ТМГ-1250 | B11: Алттранс | C11: 1250 | D11: 1791 | E11: 1070 | F11: 1856 | G11: 3135 | H11: 1803 | I11: 50х5 | J11: 2х(80х8) | K11: 80х8
A12: ТМГ-1600 | B12: Алттранс | C12: 1600 | D12: 1955 | E12: 1145 | F12: 1840 | G12: 3500 | H12: 2308 | I12: 50х5 | J12: 2х(100х10) | K12: 100х8
A13: ТМГ-2500 | B13: Алттранс | C13: 2500 | D13: 2300 | E13: 1350 | F13: 2100 | G13: 5500 | H13: 3607 | I13: 50х5 | J13: 3х(100х10) | K13: 100х10

Sheet СВЭЛ
A1: Марка | B1: Производитель | C1: Мощность (кВА) | D1: Длина (мм) | E1: Ширина (мм) | F1: Высота (мм) | G1: Масса (кг) | H1: Ном. Ток НН (А) | I1: Шины РУВН | J1: Шины РУНН (ввод) | K1: Шина PE/PEN
A2: ТМГ-160 (СВЭЛ) | B2: СВЭЛ | C2: 160 | D2: 995 | E2: 790 | F2: 1085 | G2: 720 | H2: 230 | I2: 50х5 | J2: 40х4 | K2: 40х4
A3: ТМГ-250 (СВЭЛ) | B3: СВЭЛ | C3: 250 | D3: 1055 | E3: 885 | F3: 1165 | G3: 930 | H3: 360 | I3: 50х5 | J3: 40х5 | K3: 40х4
A4: ТМГ-400 (СВЭЛ) | B4: СВЭЛ | C4: 400 | D4: 1085 | E4: 910 | F4: 1355 | G4: 1500 | H4: 577 | I4: 50х5 | J4: 50х5 | K4: 40х5
A5: ТМГ-630 (СВЭЛ) | B5: СВЭЛ | C5: 630 | D5: 1765 | E5: 1185 | F5: 1305 | G5: 1700 | H5: 909 | I5: 50х5 | J5: 80х6 | K5: 50х5
A6: ТМГ-1000 (СВЭЛ) | B6: СВЭЛ | C6: 1000 | D6: 1980 | E6: 1170 | F6: 1450 | G6: 2400 | H6: 1443 | I6: 50х5 | J6: 100х8 | K6: 80х6
A7: ТМГ-1600 (СВЭЛ) | B7: СВЭЛ | C7: 1600 | D7: 2260 | E7: 1385 | F7: 1640 | G7: 4100 | H7: 2308 | I7: 50х5 | J7: 2х(100х10) | K7: 100х8
A8: ТМГ-2500 (СВЭЛ) | B8: СВЭЛ | C8: 2500 | D8: 2325 | E8: 1495 | F8: 2015 | G8: 5040 | H8: 3607 | I8: 50х5 | J8: 3х(100х10) | K8: 100х10
A9: ТСЛ-400 (СВЭЛ) | B9: СВЭЛ | C9: 400 | D9: 1350 | E9: 850 | F9: 1450 | G9: 1600 | H9: 577 | I9: 50х5 | J9: 50х5 | K9: 40х5
A10: ТСЛ-630 (СВЭЛ) | B10: СВЭЛ | C10: 630 | D10: 1450 | E10: 900 | F10: 1600 | G10: 2100 | H10: 909 | I10: 50х5 | J10: 80х6 | K10: 50х5
A11: ТСЛ-1000 (СВЭЛ) | B11: СВЭЛ | C11: 1000 | D11: 1600 | E11: 1000 | F11: 1850 | G11: 3100 | H11: 1443 | I11: 50х5 | J11: 100х8 | K11: 80х6
A12: ТСЛ-1600 (СВЭЛ) | B12: СВЭЛ | C12: 1600 | D12: 1800 | E12: 1100 | F12: 2100 | G12: 4600 | H12: 2308 | I12: 50х5 | J12: 2х(100х10) | K12: 100х8
A13: ТСЛ-2500 (СВЭЛ) | B13: СВЭЛ | C13: 2500 | D13: 2000 | E13: 1200 | F13: 2350 | G13: 6700 | H13: 3607 | I13: 50х5 | J13: 3х(100х10) | K13: 100х10

Sheet МЭТЗ
A1: Марка | B1: Производитель | C1: Мощность (кВА) | D1: Длина (мм) | E1: Ширина (мм) | F1: Высота (мм) | G1: Масса (кг) | H1: Ном. Ток НН (А) | I1: Шины РУВН | J1: Шины РУНН (ввод) | K1: Шина PE/PEN
A2: ТМГ-25 (МЭТЗ) | B2: МЭТЗ | C2: 25 | D2: 770 | E2: 430 | F2: 900 | G2: 255 | H2: 36 | I2: 50х5 | J2: 40х4 | K2: 40х4
A3: ТМГ-40 (МЭТЗ) | B3: МЭТЗ | C3: 40 | D3: 820 | E3: 435 | F3: 950 | G3: 305 | H3: 57 | I3: 50х5 | J3: 40х4 | K3: 40х4
A4: ТМГ-63 (МЭТЗ) | B4: МЭТЗ | C4: 63 | D4: 800 | E4: 570 | F4: 920 | G4: 375 | H4: 90 | I4: 50х5 | J4: 40х4 | K4: 40х4
A5: ТМГ-100 (МЭТЗ) | B5: МЭТЗ | C5: 100 | D5: 820 | E5: 640 | F5: 1040 | G5: 485 | H5: 144 | I5: 50х5 | J5: 40х4 | K5: 40х4
A6: ТМГ-160 (МЭТЗ) | B6: МЭТЗ | C6: 160 | D6: 920 | E6: 770 | F6: 1040 | G6: 675 | H6: 230 | I6: 50х5 | J6: 40х4 | K6: 40х4
A7: ТМГ-250 (МЭТЗ) | B7: МЭТЗ | C7: 250 | D7: 1100 | E7: 830 | F7: 1120 | G7: 890 | H7: 360 | I7: 50х5 | J7: 40х5 | K7: 40х4
A8: ТМГ-400 (МЭТЗ) | B8: МЭТЗ | C8: 400 | D8: 1250 | E8: 950 | F8: 1230 | G8: 1190 | H8: 577 | I8: 50х5 | J8: 50х5 | K8: 40х5
A9: ТМГ-630 (МЭТЗ) | B9: МЭТЗ | C9: 630 | D9: 1440 | E9: 990 | F9: 1420 | G9: 1710 | H9: 909 | I9: 50х5 | J9: 80х6 | K9: 50х5
A10: ТМГ-1000 (МЭТЗ) | B10: МЭТЗ | C10: 1000 | D10: 1730 | E10: 1120 | F10: 1440 | G10: 2390 | H10: 1443 | I10: 50х5 | J10: 100х8 | K10: 80х6
A11: ТМГ-1250 (МЭТЗ) | B11: МЭТЗ | C11: 1250 | D11: 1780 | E11: 1060 | F11: 1850 | G11: 3120 | H11: 1803 | I11: 50х5 | J11: 2х(80х8) | K11: 80х8
A12: ТМГ-1600 (МЭТЗ) | B12: МЭТЗ | C12: 1600 | D12: 1950 | E12: 1140 | F12: 1830 | G12: 3490 | H12: 2308 | I12: 50х5 | J12: 2х(100х10) | K12: 100х8
A13: ТМГ-2500 (МЭТЗ) | B13: МЭТЗ | C13: 2500 | D13: 2290 | E13: 1340 | F13: 2090 | G13: 5490 | H13: 3607 | I13: 50х5 | J13: 3х(100х10) | K13: 100х10

Sheet Электрощит
A1: Марка | B1: Производитель | C1: Мощность (кВА) | D1: Длина (мм) | E1: Ширина (мм) | F1: Высота (мм) | G1: Масса (кг) | H1: Ном. Ток НН (А) | I1: Шины РУВН | J1: Шины РУНН (ввод) | K1: Шина PE/PEN
A2: ТМГ-160 (Электрощит) | B2: Электрощит | C2: 160 | D2: 940 | E2: 780 | F2: 1060 | G2: 690 | H2: 230 | I2: 50х5 | J2: 40х4 | K2: 40х4
A3: ТМГ-250 (Электрощит) | B3: Электрощит | C3: 250 | D3: 1120 | E3: 840 | F3: 1140 | G3: 900 | H3: 360 | I3: 50х5 | J3: 40х5 | K3: 40х4
A4: ТМГ-400 (Электрощит) | B4: Электрощит | C4: 400 | D4: 1270 | E4: 970 | F4: 1250 | G4: 1210 | H4: 577 | I4: 50х5 | J4: 50х5 | K4: 40х5
A5: ТМГ-630 (Электрощит) | B5: Электрощит | C5: 630 | D5: 1460 | E5: 1010 | F5: 1440 | G5: 1730 | H5: 909 | I5: 50х5 | J5: 80х6 | K5: 50х5
A6: ТМГ-1000 (Электрощит) | B6: Электрощит | C6: 1000 | D6: 1750 | E6: 1140 | F6: 1460 | G6: 2420 | H6: 1443 | I6: 50х5 | J6: 100х8 | K6: 80х6
A7: ТМГ-1600 (Электрощит) | B7: Электрощит | C7: 1600 | D7: 1970 | E7: 1160 | F7: 1860 | G7: 3520 | H7: 2308 | I7: 50х5 | J7: 2х(100х10) | K7: 100х8
A8: ТСЛ-400 (Электрощит) | B8: Электрощит | C8: 400 | D8: 1360 | E8: 860 | F8: 1460 | G8: 1620 | H8: 577 | I8: 50х5 | J8: 50х5 | K8: 40х5
A9: ТСЛ-630 (Электрощит) | B9: Электрощит | C9: 630 | D9: 1460 | E9: 910 | F9: 1610 | G9: 2120 | H9: 909 | I9: 50х5 | J9: 80х6 | K9: 50х5
A10: ТСЛ-1000 (Электрощит) | B10: Электрощит | C10: 1000 | D10: 1610 | E10: 1010 | F10: 1860 | G10: 3120 | H10: 1443 | I10: 50х5 | J10: 100х8 | K10: 80х6
A11: ТСЛ-1600 (Электрощит) | B11: Электрощит | C11: 1600 | D11: 1810 | E11: 1110 | F11: 2110 | G11: 4620 | H11: 2308 | I11: 50х5 | J11: 2х(100х10) | K11: 100х8
A12: ТСЛ-2500 (Электрощит) | B12: Электрощит | C12: 2500 | D12: 2010 | E12: 1210 | F12: 2360 | G12: 6720 | H12: 3607 | I12: 50х5 | J12: 3х(100х10) | K12: 100х10

Sheet Трансформер
A1: Марка | B1: Производитель | C1: Мощность (кВА) | D1: Длина (мм) | E1: Ширина (мм) | F1: Высота (мм) | G1: Масса (кг) | H1: Ном. Ток НН (А) | I1: Шины РУВН | J1: Шины РУНН (ввод) | K1: Шина PE/PEN
A2: ТСЛ-250 (Трансформер) | B2: Трансформер | C2: 250 | D2: 1210 | E2: 760 | F2: 1310 | G2: 1160 | H2: 360 | I2: 50х5 | J2: 40х5 | K2: 40х4
A3: ТСЛ-400 (Трансформер) | B3: Трансформер | C3: 400 | D3: 1360 | E3: 860 | F3: 1460 | G3: 1610 | H3: 577 | I3: 50х5 | J3: 50х5 | K3: 40х5
A4: ТСЛ-630 (Трансформер) | B4: Трансформер | C4: 630 | D4: 1460 | E4: 910 | F4: 1610 | G4: 2110 | H4: 909 | I4: 50х5 | J4: 80х6 | K4: 50х5
A5: ТСЛ-1000 (Трансформер) | B5: Трансформер | C5: 1000 | D5: 1610 | E5: 1010 | F5: 1860 | G5: 3110 | H5: 1443 | I5: 50х5 | J5: 100х8 | K5: 80х6
A6: ТСЛ-1600 (Трансформер) | B6: Трансформер | C6: 1600 | D6: 1810 | E6: 1110 | F6: 2110 | G6: 4610 | H6: 2308 | I6: 50х5 | J6: 2х(100х10) | K6: 100х8
A7: ТСЛ-2500 (Трансформер) | B7: Трансформер | C7: 2500 | D7: 2010 | E7: 1210 | F7: 2360 | G7: 6710 | H7: 3607 | I7: 50х5 | J7: 3х(100х10) | K7: 100х10

Sheet Алагеум
A1: Марка | B1: Производитель | C1: Мощность (кВА) | D1: Длина (мм) | E1: Ширина (мм) | F1: Высота (мм) | G1: Масса (кг) | H1: Ном. Ток НН (А) | I1: Шины РУВН | J1: Шины РУНН (ввод) | K1: Шина PE/PEN
A2: ТМГ-25 (Алагеум) | B2: Алагеум | C2: 25 | D2: 780 | E2: 440 | F2: 910 | G2: 255 | H2: 36 | I2: 50х5 | J2: 40х4 | K2: 40х4
A3: ТМГ-40 (Алагеум) | B3: Алагеум | C3: 40 | D3: 830 | E3: 440 | F3: 960 | G3: 310 | H3: 57 | I3: 50х5 | J3: 40х4 | K3: 40х4
A4: ТМГ-63 (Алагеум) | B4: Алагеум | C4: 63 | D4: 810 | E4: 580 | F4: 930 | G4: 380 | H4: 90 | I4: 50х5 | J4: 40х4 | K4: 40х4
A5: ТМГ-100 (Алагеум) | B5: Алагеум | C5: 100 | D5: 830 | E5: 650 | F5: 1050 | G5: 490 | H5: 144 | I5: 50х5 | J5: 40х4 | K5: 40х4
A6: ТМГ-160 (Алагеум) | B6: Алагеум | C6: 160 | D6: 930 | E6: 780 | F6: 1050 | G6: 680 | H6: 230 | I6: 50х5 | J6: 40х4 | K6: 40х4
A7: ТМГ-250 (Алагеум) | B7: Алагеум | C7: 250 | D7: 1100 | E7: 840 | F7: 1130 | G7: 900 | H7: 360 | I7: 50х5 | J7: 40х5 | K7: 40х4
A8: ТМГ-400 (Алагеум) | B8: Алагеум | C8: 400 | D8: 1260 | E8: 960 | F8: 1240 | G8: 1200 | H8: 577 | I8: 50х5 | J8: 50х5 | K8: 40х5
A9: ТМГ-630 (Алагеум) | B9: Алагеум | C9: 630 | D9: 1450 | E9: 1000 | F9: 1430 | G9: 1720 | H9: 909 | I9: 50х5 | J9: 80х6 | K9: 50х5
A10: ТМГ-1000 (Алагеум) | B10: Алагеум | C10: 1000 | D10: 1740 | E10: 1130 | F10: 1450 | G10: 2400 | H10: 1443 | I10: 50х5 | J10: 100х8 | K10: 80х6
A11: ТМГ-1250 (Алагеум) | B11: Алагеум | C11: 1250 | D11: 1790 | E11: 1070 | F11: 1860 | G11: 3140 | H11: 1803 | I11: 50х5 | J11: 2х(80х8) | K11: 80х8
A12: ТМГ-1600 (Алагеум) | B12: Алагеум | C12: 1600 | D12: 1960 | E12: 1150 | F12: 1840 | G12: 3500 | H12: 2308 | I12: 50х5 | J12: 2х(100х10) | K12: 100х8
A13: ТМГ-2500 (Алагеум) | B13: Алагеум | C13: 2500 | D13: 2300 | E13: 1350 | F13: 2100 | G13: 5500 | H13: 3607 | I13: 50х5 | J13: 3х(100х10) | K13: 100х10
... A21: ТСЛ-2500 (Алагеум) | B21: Алагеум | C21: 2500 | D21: 2000 | E21: 1200 | F21: 2350 | G21: 6700 | H21: 3607 | I21: 50х5 | J21: 3х(100х10) | K21: 100х10

Sheet Списки
A1: ManufacturerList | B1: Алттранс | C1: СВЭЛ | D1: МЭТЗ | E1: Электрощит | F1: Трансформер | G1: Алагеум | H1: empty_list | I1: steel_type | J1: steel_thickness | K1: channel_size | L1: ral_colors | M1: grid_company | N1: manuf_pvr | O1: manuf_re | P1: manuf_rps | Q1: manuf_av | R1: yn | S1: ruvn_type | T1: ruvn_switch | U1: ruvn_nom | V1: volt | W1: fuse | X1: fuse_nom | Y1: Толщина | Z1: Вес_м2 | AA1: Швеллер | AB1: Вес_м
A2: Алттранс | B2: ТМГ-25 | C2: ТМГ-160 (СВЭЛ) | D2: ТМГ-25 (МЭТЗ) | E2: ТМГ-160 (Электрощит) | F2: ТСЛ-250 (Трансформер) | G2: ТМГ-25 (Алагеум) | H2: - | I2: Холоднокатаная (х.к.) | J2: 1.5 | K2: 6П | L2: RAL 7035 (Светло-серый) | M2: Россети | N2: КЭАЗ | O2: КЭАЗ | P2: Кореневский завод НВА | Q2: КЭАЗ | R2: Да | S2: Тупиковая | T2: ВНА | U2: 400 | V2: 10 кВ | W2: ПКТ-101 | X2: Нет | Y2: 1.5 | Z2: 11.78 | AA2: 6П | AB2: 7.09
A3: СВЭЛ | B3: ТМГ-40 | C3: ТМГ-250 (СВЭЛ) | D3: ТМГ-40 (МЭТЗ) | E3: ТМГ-250 (Электрощит) | F3: ТСЛ-400 (Трансформер) | G3: ТМГ-40 (Алагеум) | I3: Оцинкованная | J3: 2.0 | K3: 6У | L3: RAL 7040 (Серый окованный) | M3: АО Облкоммунэнерго | N3: IEK | O3: Кореневский завод НВА | P3: КЭАЗ | Q3: Контактор | R3: Нет | S3: Проходная | T3: РВЗ | U3: 630 | V3: 6 кВ | W3: ПКТ-102 | X3: 2А | Y3: 2.0 | Z3: 15.7 | AA3: 6У | AB3: 7.09
A4: МЭТЗ | B4: ТМГ-63 | C4: ТМГ-400 (СВЭЛ) | D4: ТМГ-63 (МЭТЗ) | E4: ТМГ-400 (Электрощит) | F4: ТСЛ-630 (Трансформер) | G4: ТМГ-63 (Алагеум) | J4: 2.5 | K4: 8П | L4: RAL 6005 (Зеленый мох) | M4: АО ЕЭСК | N4: EKF | O4: IEK | P4: CHINT | Q4: IEK | S4: Нет | T4: Нет | U4: 1000 | W4: ПКТ-103 | X4: 3.15А | Y4: 2.5 | Z4: 19.63 | AA4: 8П | AB4: 7.05
A5: Электрощит | B5: ТМГ-100 | C5: ТМГ-630 (СВЭЛ) | D5: ТМГ-100 (МЭТЗ) | E5: ТМГ-630 (Электрощит) | F5: ТСЛ-1000 (Трансформер) | G5: ТМГ-100 (Алагеум) | J5: 3.0 | K5: 8У | L5: RAL 5005 (Сигнальный синий) | M5: ОАО РЖД | N5: CHINT | O5: CHINT | Q5: EKF | W5: Нет | X5: 5А | Y5: 3.0 | Z5: 23.55 | AA5: 8У | AB5: 7.05
A6: Трансформер | B6: ТМГ-160 | C6: ТМГ-1000 (СВЭЛ) | D6: ТМГ-160 (МЭТЗ) | E6: ТМГ-1000 (Электрощит) | F6: ТСЛ-1600 (Трансформер) | G6: ТМГ-160 (Алагеум) | K6: 10П | L6: RAL 9010 (Чистый белый) | M6: Без логотипа (по ТЗ) | N6: Апатор-Электро | Q6: ДКС (DKC) | X6: 8А | Z6: 1000 | AA6: 10П | AB6: 8.59
A7: Алагеум | B7: ТМГ-250 | C7: ТМГ-1600 (СВЭЛ) | D7: ТМГ-250 (МЭТЗ) | E7: ТМГ-1600 (Электрощит) | F7: ТСЛ-2500 (Трансформер) | G7: ТМГ-250 (Алагеум) | K7: 10У | L7: RAL 9005 (Глубокий черный) | Q7: CHINT | X7: 10А | Z7: 1600 | AA7: 10У | AB7: 8.59
B8: ТМГ-400 | C8: ТМГ-2500 (СВЭЛ) | D8: ТМГ-400 (МЭТЗ) | E8: ТСЛ-400 (Электрощит) | G8: ТМГ-400 (Алагеум) | K8: 12П | L8: RAL 1015 (Светлая слоновая кость) | X8: 16А | Z8: 2500 | AA8: 12П | AB8: 10.4
B9: ТМГ-630 | C9: ТСЛ-400 (СВЭЛ) | D9: ТМГ-630 (МЭТЗ) | E9: ТСЛ-630 (Электрощит) | G9: ТМГ-630 (Алагеум) | K9: 12У | L9: RAL 3020 (Сигнальный красный) | X9: 20А | AA9: 12У | AB9: 10.4
B10: ТМГ-1000 | C10: ТСЛ-630 (СВЭЛ) | D10: ТМГ-1000 (МЭТЗ) | E10: ТСЛ-1000 (Электрощит) | G10: ТМГ-1000 (Алагеум) | K10: 14П | L10: Другой (указать в примечании) | X10: 31.5А | AA10: 14П | AB10: 12.3
B11: ТМГ-1250 | C11: ТСЛ-1000 (СВЭЛ) | D11: ТМГ-1250 (МЭТЗ) | E11: ТСЛ-1600 (Электрощит) | G11: ТМГ-1250 (Алагеум) | K11: 14У | X11: 40А | AA11: 14У | AB11: 12.3
B12: ТМГ-1600 | C12: ТСЛ-1600 (СВЭЛ) | D12: ТМГ-1600 (МЭТЗ) | E12: ТСЛ-2500 (Электрощит) | G12: ТМГ-1600 (Алагеум) | K12: 16П | X12: 50А | AA12: 16П | AB12: 14.2
B13: ТМГ-2500 | C13: ТСЛ-2500 (СВЭЛ) | D13: ТМГ-2500 (МЭТЗ) | G13: ТМГ-2500 (Алагеум) | K13: 16У | X13: 63А | AA13: 16У | AB13: 14.2
G14: ТСЛ-250 (Алагеум) | X14: 80А | AB14: 400
G15: ТСЛ-400 (Алагеум) | X15: 100А | AB15: 630
G16: ТСЛ-630 (Алагеум) | X16: 160А | AB16: 1000
G17: ТСЛ-1000 (Алагеум) | AB17: 1600
G18: ТСЛ-1250 (Алагеум) | AB18: 2000
G19: ТСЛ-1600 (Алагеум) | AB19: 2500
G20: ТСЛ-2000 (Алагеум) | AB20: 3150
G21: ТСЛ-2500 (Алагеум) | AB21: 4000

Sheet Габариты
A1: ПАСПОРТ МЕТАЛЛОКОНСТРУКЦИИ И ГАБАРИТЫ
A3: Сетевая компания: | B3: ='Расчет КТПН'!B3
A4: Материал корпуса: | B4: ='Расчет КТПН'!B11
A5: Толщина металла (мм): | B5: ='Расчет КТПН'!D11
A6: Основание (Швеллер): | B6: ='Расчет КТПН'!B12
A7: Цвет окраски корпуса: | B7: ='Расчет КТПН'!B13
A8: Цвет окраски дверей: | B8: ='Расчет КТПН'!D13
A10: Итоговая длина КТПН (мм): | B10: ='Расчет КТПН'!D54
A11: Итоговая ширина КТПН (мм): | B11: ='Расчет КТПН'!D55
A12: Итоговая высота КТПН (мм): | B12: ='Расчет КТПН'!D56
A14: Масса основания (кг): | B14: ='Расчет КТПН'!D57
A15: Масса корпуса (без основания) (кг): | B15: ='Расчет КТПН'!D58
A16: Масса силового трансформатора (кг): | B16: ='Расчет КТПН'!E8
A17: Итоговая Масса Брутто (кг): | B17: ='Расчет КТПН'!D59

Sheet Приказ на работу
A1: В работу Конструкторская служба Отдел Снабжения
A3: Приказ № _______ от ___.___.202_ г.
A4: На запуск в производство электрооборудования
A6: Подписи: ________________ / М.М. Жамалетдинов ________________ / М.Д. Богатенков
A8: Заводской номер / Дата Сети / Типовой проект | B8: ="№________ / __.__.202_ г." & CHAR(10) & 'Расчет КТПН'!B3 & " / ________________" | C8: подпись
A9: Напряжение / Мощность / ТМГ | B9: ='Расчет КТПН'!B22 & " / " & VLOOKUP('Расчет КТПН'!B5, БД_Трансформаторы!$A$2:$K$200, 3, FALSE) & " кВА / " & 'Расчет КТПН'!B5
A10: ПКТ(101,102,103) Тип КТПН, Габариты: ШхДхВ | B10: ='Расчет КТПН'!B25 & " " & 'Расчет КТПН'!D25 & CHAR(10) & 'Расчет КТПН'!B23 & CHAR(10) & 'Расчет КТПН'!D55 & "x" & 'Расчет КТПН'!D54 & "x" & 'Расчет КТПН'!D56
A11: Металл корпуса | B11: ='Расчет КТПН'!B11 & " " & 'Расчет КТПН'!D11 & " мм"
A12: Металл Пола | B12: ="Швеллер " & 'Расчет КТПН'!B12
A13: Кол-во дверей тр-ра Цвет корпуса / толщина ЛКП | B13: ="Двухстворчатые распашные двери" & CHAR(10) & 'Расчет КТПН'!B13 & " / ____ мкм"
A14: Цвет дверей / толщина ЛКП | B14: ='Расчет КТПН'!D13 & " / ____ мкм"
A15: Разъединитель РУВН | B15: ='Расчет КТПН'!B24 & " " & 'Расчет КТПН'!D24 & "А"
A16: Аппаратура РУНН (Ввод) | B16: =IF('Расчет КТПН'!B29="Да", "ПВР " & 'Расчет КТПН'!D29 & "А (" & 'Расчет КТПН'!B30 & ")", IF('Расчет КТПН'!B31="Да", "Рубильник РЕ " & 'Расчет КТПН'!D31 & "А (" & 'Расчет КТПН'!B32 & ")", IF('Расчет КТПН'!B33="Да", "Вводной АВ " & 'Расчет КТПН'!D33 & "А (" & 'Расчет КТПН'!B34 & ")", "Не установлен")))
A17: Ошиновка РУНН (Ввод) | B17: ='Расчет КТПН'!D49
A18: Ошиновка РУВН | B18: ='Расчет КТПН'!B49

Sheet Чек-лист ОТК
A1: Акт осмотра КТПН №_______
A2: г. _____________________ | D2: ___ .________. 202_ г.
A4: Состав комиссии: Инженер по качеству Ершов А.М. / _________________________
A6: Критерий проверки | B6: Статус | C6: Оценка | D6: Подпись
A7: ОБОРУДОВАНИЕ
A8: Наличие перечня оборудования | B8: [ Да / Нет ]
A9: Наличие ТЗ от заказчика | B9: [ Да / Нет ]
A10: Сравнить ТЗ заказчика с перечнем оборудования | B10: [ Да / Нет ]
A11: Сравнить ТЗ заказчика со схемами | B11: [ Да / Нет ]
A12: Сравнить фактическое оборудования с перечнем оборудования | B12: [ Да / Нет ]
A13: Сравнить фактическое оборудования со схемами | B13: [ Да / Нет ]
A14: ВНЕШНИЙ КОРПУС
A15: ="Проверка габаритов: Ш=" & 'Расчет КТПН'!D55 & " Д=" & 'Расчет КТПН'!D54 & " В=" & 'Расчет КТПН'!D56 | B15: [ Да / Нет ]
A16: ="Проверка металла: " & 'Расчет КТПН'!B11 & " " & 'Расчет КТПН'!D11 & "мм" | B16: [ Да / Нет ]
A17: Проверка на отсутствие мусора до закрытия панелями | B17: [ Да / Нет ]
A18: Герметик по основанию | B18: [ Да / Нет ]
A19: Черное основание | B19: [ Да / Нет ]
A20: Проушины в черный цвет | B20: [ Да / Нет ]
A21: Маркировка проушин | B21: [ Да / Нет ]
A22: Наличие грибка (630 кВ и выше) | B22: [ Да / Нет ]
A23: Наличие траверсы на крыши (при условии, что В/В) | B23: [ Да / Нет ]
A24: Наличие пластиковой таблички. ТП-86045 | B24: [ Да / Нет ]
A25: ="Окраска (Корпус): " & 'Расчет КТПН'!B13 | B25: [ Да / Нет ]
A26: Нагар | B26: [ Да / Нет ]
A27: Сколы/царапины | B27: [ Да / Нет ]
A28: Грязь | B28: [ Да / Нет ]
A29: ДВЕРИ РУНН СНАРУЖИ
A30: Открыть/закрыть дверь | B30: [ Да / Нет ]
A31: Открыть/закрыть ригельный замок | B31: [ Да / Нет ]
A32: Открыть/закрыть сетевой замок | B32: [ Да / Нет ]
A33: Защитный козырек (вылет) | B33: [ Да / Нет ]
A34: ="Нанести логотип/надпись: " & 'Расчет КТПН'!B3 | B34: [ Да / Нет ]
A35: Приклепать знак «Молния» | B35: [ Да / Нет ]
A36: На двери нанести надпись «РУ-6 кВ/10кВ» | B36: [ Да / Нет ]
A37: ="Окраска (Двери): " & 'Расчет КТПН'!D13 | B37: [ Да / Нет ]
A38: ВЫСОКОВОЛЬТНЫЙ ПОРТАЛ 6(10) кВ
A39: Открыть/закрыть замок | B39: [ Да / Нет ]
A40: Приварить траверсу для установки изоляторов. | B40: [ Да / Нет ]
A41: Монтаж через прокладку (должна выпирать за габарит изолятора) | B41: [ Да / Нет ]
A42: Установить замки под треугольный ключ | B42: [ Да / Нет ]
...
